<?xml version='1.0'?>

<robot name="myrobot" xmlns:xacro="http://www.ros.org/wiki/xacro">



  <xacro:include filename="$(find mybot_description)/urdf/mybot.gazebo" />
  <xacro:include filename="$(find mybot_description)/urdf/materials.xacro" />
  <xacro:include filename="$(find mybot_description)/urdf/macros.xacro" />

  <pose>0 0 0 0 0 0</pose>


  <link name='chassis'>
  
    <!--self_collide>true</self_collide-->
  
    <pose>0 0 0.0696 0 0 0</pose>

    <inertial>
      <mass value="2.1"/>
      <origin xyz="0.0 0.0 0.0" rpy=" 0 0 0"/>
      <inertia
          ixx="0.0106715" ixy="0.007932" ixz="0.0005141"
          iyy="0.0207505" iyz="-0.0005949"
          izz="0.029041"
      />
    </inertial>

    <collision name='collision'>
      <origin xyz="0 0 0" rpy=" 0 0 0"/>
      <geometry>
        <box size=".2 .1 .089"/>
      </geometry>
    </collision>

    <visual name='chassis_visual'>
      <origin xyz="0 0 0" rpy=" 0 0 0"/>
      <geometry>
        <box size=".2 .1 .089"/>
      </geometry>
    </visual>


    <collision name='caster_collision'>
      <origin xyz="0 0 0" rpy=" 0 0 0"/>
      <geometry>
        <sphere radius="0.031"/>
      </geometry>
      <surface>
        <friction>
          <ode>
            <mu>0</mu>
            <mu2>0</mu2>
            <slip1>1.0</slip1>
            <slip2>1.0</slip2>
          </ode>
        </friction>
      </surface>
    </collision>

    <visual name='caster_visual'>
      <origin xyz="0 0 0" rpy=" 0 0 0"/>
      <geometry>
        <sphere radius="0.031"/>
      </geometry>
    </visual>
    
    
    <collision name='right_pad'>
      <origin xyz="0 -0.08 -0.0385" rpy=" 0 0 0"/>
      <geometry>
        <box size=".08 .029 .055"/>
      </geometry>
    </collision>

    <!--visual name='right_pad'>
      <origin xyz="0 -0.08 -0.0385" rpy=" 0 0 0"/>
      <geometry>
        <box size=".08 .029 .055"/>
      </geometry>
    </visual-->
    
    <collision name='left_pad'>
      <origin xyz="0 0.08 -0.0385" rpy=" 0 0 0"/>
      <geometry>
        <box size=".08 .029 .055"/>
      </geometry>
    </collision>

    <!--visual name='left_pad'>
      <origin xyz="0 0.08 -0.0385" rpy=" 0 0 0"/>
      <geometry>
        <box size=".08 .029 .055"/>
      </geometry>
    </visual-->
    
  </link>





  <link name="right_wheel">
    
    <!--self_collide>true</self_collide-->
    
    <!-- * * * Inertial Definitions * * * -->
    <inertial>
      <mass value="0.012"/>
      <origin xyz="0 0 0" rpy=" 0 0 0"/>
      <inertia
          ixx="0.01" ixy="0" ixz="0"
          iyy="0.01" iyz="0"
          izz="0.01"
      />
    </inertial>
    <!-- * * * Inertial Definitions end * * * -->
    
    <!-- * * * Visual Definitions * * * -->
    <visual name='ins'>
      <geometry>
        <cylinder length="0.04" radius="0.0275" />
      </geometry>
      <origin rpy="1.57075 0 0" xyz="0 0 0" />
    </visual>
    
   <visual name='krom_1'>
      <geometry>
        <cylinder length="0.005" radius="0.0335" />
      </geometry>
      <origin rpy="1.57075 0 0" xyz="0 0.0175 0" />
    </visual>
  
    <visual name='krom_2'>
      <geometry>
        <cylinder length="0.005" radius="0.0335" />
      </geometry>
      <origin rpy="1.57075 0 0" xyz="0 -0.0175 0" />
    </visual>
  
    <visual name='tr_1'>
      <geometry>
        <box size="0.01 0.03 0.0035"/>
      </geometry>
      <origin rpy="0 0 0" xyz="0 0 0.0285" />
    </visual>
  
    <visual name='tr_2'>
      <geometry>
        <box size="0.01 0.03 0.0035"/>
      </geometry>
      <origin rpy="0 0 0" xyz="0 0 -0.0285" />
    </visual>
  
  	<visual name='tr_3'>
      <geometry>
        <box size="0.01 0.03 0.0035"/>
      </geometry>
      <origin rpy="0 1.57075 0" xyz="0.0285 0 0" />
    </visual>
  
    <visual name='tr_4'>
      <geometry>
        <box size="0.01 0.03 0.0035"/>
      </geometry>
      <origin rpy="0 1.57075 0" xyz="-0.0285 0 0" />
    </visual>
  
    <visual name='tr_5'>
      <geometry>
        <box size="0.01 0.03 0.0035"/>
      </geometry>
      <origin rpy="0 -0.785398 0" xyz="-0.0201525 0 0.0201525" />
    </visual>
  
    <visual name='tr_6'>
      <geometry>
        <box size="0.01 0.03 0.0035"/>
      </geometry>
      <origin rpy="0 -0.785398 0" xyz="0.0201525 0 -0.0201525" />
    </visual>
  
  	<visual name='tr_7'>
      <geometry>
        <box size="0.01 0.03 0.0035"/>
      </geometry>
      <origin rpy="0 0.785398 0" xyz="0.0201525 0 0.0201525" />
    </visual>
  
    <visual name='tr_8'>
      <geometry>
        <box size="0.01 0.03 0.0035"/>
      </geometry>
      <origin rpy="0 0.785398 0" xyz="-0.0201525 0 -0.0201525" />
    </visual>
    <!-- * * * Visual Definitions end * * * -->
    
    
    <!-- * * * Collision Definitions * * * -->
    <collision name='coll_ins'>
      <geometry>
        <cylinder length="0.04" radius="0.0275" />
      </geometry>
      <origin rpy="1.57075 0 0" xyz="0 0 0" />
    </collision>
    
     <collision name='coll_krom_1'>
      <geometry>
        <cylinder length="0.005" radius="0.0335" />
      </geometry>
      <origin rpy="1.57075 0 0" xyz="0 0.0175 0" />
    </collision>
  
    <collision name='coll_krom_2'>
      <geometry>
        <cylinder length="0.005" radius="0.0335" />
      </geometry>
      <origin rpy="1.57075 0 0" xyz="0 -0.0175 0" />
    </collision>
    
    <collision name='coll_tr_1'>
      <geometry>
        <box size="0.01 0.03 0.0035"/>
      </geometry>
      <origin rpy="0 0 0" xyz="0 0 0.0285" />
    </collision>
  
    <collision name='coll_tr_2'>
      <geometry>
        <box size="0.01 0.03 0.0035"/>
      </geometry>
      <origin rpy="0 0 0" xyz="0 0 -0.0285" />
    </collision>
  
  	<collision name='coll_tr_3'>
      <geometry>
        <box size="0.01 0.03 0.0035"/>
      </geometry>
      <origin rpy="0 1.57075 0" xyz="0.0285 0 0" />
    </collision>
  
    <collision name='coll_tr_4'>
      <geometry>
        <box size="0.01 0.03 0.0035"/>
      </geometry>
      <origin rpy="0 1.57075 0" xyz="-0.0285 0 0" />
    </collision>
  
    <collision name='coll_tr_5'>
      <geometry>
        <box size="0.01 0.03 0.0035"/>
      </geometry>
      <origin rpy="0 -0.785398 0" xyz="-0.0201525 0 0.0201525" />
    </collision>
  
    <collision name='coll_tr_6'>
      <geometry>
        <box size="0.01 0.03 0.0035"/>
      </geometry>
      <origin rpy="0 -0.785398 0" xyz="0.0201525 0 -0.0201525" />
    </collision>
  
  	<collision name='coll_tr_7'>
      <geometry>
        <box size="0.01 0.03 0.0035"/>
      </geometry>
      <origin rpy="0 0.785398 0" xyz="0.0201525 0 0.0201525" />
    </collision>
  
    <collision name='coll_tr_8'>
      <geometry>
        <box size="0.01 0.03 0.0035"/>
      </geometry>
      <origin rpy="0 0.785398 0" xyz="-0.0201525 0 -0.0201525" />
    </collision>
    <!-- * * * Collision Definitions end * * * -->

  </link>


  <link name="left_wheel">
    
    <!-- * * * Inertial Definitions * * * -->
    <inertial>
      <mass value="0.012"/>
      <origin xyz="0 0 0" rpy=" 0 0 0"/>
      <inertia
          ixx="0.01" ixy="0" ixz="0"
          iyy="0.01" iyz="0"
          izz="0.01"
      />
    </inertial>
    <!-- * * * Inertial Definitions end * * * -->
    
    <!-- * * * Visual Definitions * * * -->
    <visual name='ins'>
      <geometry>
        <cylinder length="0.04" radius="0.0275" />
      </geometry>
      <origin rpy="1.57075 0 0" xyz="0 0 0" />
    </visual>
    
    <visual name='krom_1'>
      <geometry>
        <cylinder length="0.005" radius="0.0335" />
      </geometry>
      <origin rpy="1.57075 0 0" xyz="0 0.0175 0" />
    </visual>
  
    <visual name='krom_2'>
      <geometry>
        <cylinder length="0.005" radius="0.0335" />
      </geometry>
      <origin rpy="1.57075 0 0" xyz="0 -0.0175 0" />
    </visual>
  
    <visual name='tr_1'>
      <geometry>
        <box size="0.01 0.03 0.0035"/>
      </geometry>
      <origin rpy="0 0 0" xyz="0 0 0.0285" />
    </visual>
  
    <visual name='tr_2'>
      <geometry>
        <box size="0.01 0.03 0.0035"/>
      </geometry>
      <origin rpy="0 0 0" xyz="0 0 -0.0285" />
    </visual>
  
  	<visual name='tr_3'>
      <geometry>
        <box size="0.01 0.03 0.0035"/>
      </geometry>
      <origin rpy="0 1.57075 0" xyz="0.0285 0 0" />
    </visual>
  
    <visual name='tr_4'>
      <geometry>
        <box size="0.01 0.03 0.0035"/>
      </geometry>
      <origin rpy="0 1.57075 0" xyz="-0.0285 0 0" />
    </visual>
  
    <visual name='tr_5'>
      <geometry>
        <box size="0.01 0.03 0.0035"/>
      </geometry>
      <origin rpy="0 -0.785398 0" xyz="-0.0201525 0 0.0201525" />
    </visual>
  
    <visual name='tr_6'>
      <geometry>
        <box size="0.01 0.03 0.0035"/>
      </geometry>
      <origin rpy="0 -0.785398 0" xyz="0.0201525 0 -0.0201525" />
    </visual>
  
  	<visual name='tr_7'>
      <geometry>
        <box size="0.01 0.03 0.0035"/>
      </geometry>
      <origin rpy="0 0.785398 0" xyz="0.0201525 0 0.0201525" />
    </visual>
  
    <visual name='tr_8'>
      <geometry>
        <box size="0.01 0.03 0.0035"/>
      </geometry>
      <origin rpy="0 0.785398 0" xyz="-0.0201525 0 -0.0201525" />
    </visual>
    <!-- * * * Visual Definitions end * * * -->
    
    
    <!-- * * * Collision Definitions * * * -->
    <collision name='coll_ins'>
      <geometry>
        <cylinder length="0.04" radius="0.0275" />
      </geometry>
      <origin rpy="1.57075 0 0" xyz="0 0 0" />
    </collision>
    
    <collision name='coll_krom_1'>
      <geometry>
        <cylinder length="0.005" radius="0.0335" />
      </geometry>
      <origin rpy="1.57075 0 0" xyz="0 0.0175 0" />
    </collision>
  
    <collision name='coll_krom_2'>
      <geometry>
        <cylinder length="0.005" radius="0.0335" />
      </geometry>
      <origin rpy="1.57075 0 0" xyz="0 -0.0175 0" />
    </collision>
    
    <collision name='coll_tr_1'>
      <geometry>
        <box size="0.01 0.03 0.0035"/>
      </geometry>
      <origin rpy="0 0 0" xyz="0 0 0.0285" />
    </collision>
  
    <collision name='coll_tr_2'>
      <geometry>
        <box size="0.01 0.03 0.0035"/>
      </geometry>
      <origin rpy="0 0 0" xyz="0 0 -0.0285" />
    </collision>
  
  	<collision name='coll_tr_3'>
      <geometry>
        <box size="0.01 0.03 0.0035"/>
      </geometry>
      <origin rpy="0 1.57075 0" xyz="0.0285 0 0" />
    </collision>
  
    <collision name='coll_tr_4'>
      <geometry>
        <box size="0.01 0.03 0.0035"/>
      </geometry>
      <origin rpy="0 1.57075 0" xyz="-0.0285 0 0" />
    </collision>
  
    <collision name='coll_tr_5'>
      <geometry>
        <box size="0.01 0.03 0.0035"/>
      </geometry>
      <origin rpy="0 -0.785398 0" xyz="-0.0201525 0 0.0201525" />
    </collision>
  
    <collision name='coll_tr_6'>
      <geometry>
        <box size="0.01 0.03 0.0035"/>
      </geometry>
      <origin rpy="0 -0.785398 0" xyz="0.0201525 0 -0.0201525" />
    </collision>
  
  	<collision name='coll_tr_7'>
      <geometry>
        <box size="0.01 0.03 0.0035"/>
      </geometry>
      <origin rpy="0 0.785398 0" xyz="0.0201525 0 0.0201525" />
    </collision>
  
    <collision name='coll_tr_8'>
      <geometry>
        <box size="0.01 0.03 0.0035"/>
      </geometry>
      <origin rpy="0 0.785398 0" xyz="-0.0201525 0 -0.0201525" />
    </collision>
    <!-- * * * Collision Definitions end * * * -->

  </link>





  <joint type="continuous" name="left_wheel_hinge">
    <origin xyz="-0.074 0.08 -0.0385" rpy="0 0 0"/>
    <child link="left_wheel"/>
    <parent link="chassis"/>
    <axis xyz="0 1 0" rpy="0 0 0"/>
    <limit effort="100" velocity="100"/>
    <joint_properties damping="0.0" friction="0.0"/>
  </joint>

  <joint type="continuous" name="right_wheel_hinge">
    <origin xyz="-0.074 -0.08 -0.0385" rpy="0 0 0"/>  <!-- -0.0761  -0.072 -->
    <child link="right_wheel"/>
    <parent link="chassis"/>
    <axis xyz="0 1 0" rpy="0 0 0"/>
    <limit effort="100" velocity="100"/>
    <joint_properties damping="0.0" friction="0.0"/>
  </joint>
  
  
  
  
  
  
  
  
  
  
  
  
  
  
  
  
  
  
  
  
  
  
  
  
  
  
  
  
  
  
  
  
  
  
  
  
  
  
  
  
    <link name="right_wheel_forw">
    
    <!-- * * * Inertial Definitions * * * -->
    <inertial>
      <mass value="0.012"/>
      <origin xyz="0 0 0" rpy=" 0 0 0"/>
      <inertia
          ixx="0.01" ixy="0" ixz="0"
          iyy="0.01" iyz="0"
          izz="0.01"
      />
    </inertial>
    <!-- * * * Inertial Definitions end * * * -->
    
    <!-- * * * Visual Definitions * * * -->
    <visual name='ins'>
      <geometry>
        <cylinder length="0.04" radius="0.0275" />
      </geometry>
      <origin rpy="1.57075 0 0" xyz="0 0 0" />
    </visual>
    
   <visual name='krom_1'>
      <geometry>
        <cylinder length="0.005" radius="0.0335" />
      </geometry>
      <origin rpy="1.57075 0 0" xyz="0 0.0175 0" />
    </visual>
  
    <visual name='krom_2'>
      <geometry>
        <cylinder length="0.005" radius="0.0335" />
      </geometry>
      <origin rpy="1.57075 0 0" xyz="0 -0.0175 0" />
    </visual>
  
    <visual name='tr_1'>
      <geometry>
        <box size="0.01 0.03 0.0035"/>
      </geometry>
      <origin rpy="0 0 0" xyz="0 0 0.0285" />
    </visual>
  
    <visual name='tr_2'>
      <geometry>
        <box size="0.01 0.03 0.0035"/>
      </geometry>
      <origin rpy="0 0 0" xyz="0 0 -0.0285" />
    </visual>
  
  	<visual name='tr_3'>
      <geometry>
        <box size="0.01 0.03 0.0035"/>
      </geometry>
      <origin rpy="0 1.57075 0" xyz="0.0285 0 0" />
    </visual>
  
    <visual name='tr_4'>
      <geometry>
        <box size="0.01 0.03 0.0035"/>
      </geometry>
      <origin rpy="0 1.57075 0" xyz="-0.0285 0 0" />
    </visual>
  
    <visual name='tr_5'>
      <geometry>
        <box size="0.01 0.03 0.0035"/>
      </geometry>
      <origin rpy="0 -0.785398 0" xyz="-0.0201525 0 0.0201525" />
    </visual>
  
    <visual name='tr_6'>
      <geometry>
        <box size="0.01 0.03 0.0035"/>
      </geometry>
      <origin rpy="0 -0.785398 0" xyz="0.0201525 0 -0.0201525" />
    </visual>
  
  	<visual name='tr_7'>
      <geometry>
        <box size="0.01 0.03 0.0035"/>
      </geometry>
      <origin rpy="0 0.785398 0" xyz="0.0201525 0 0.0201525" />
    </visual>
  
    <visual name='tr_8'>
      <geometry>
        <box size="0.01 0.03 0.0035"/>
      </geometry>
      <origin rpy="0 0.785398 0" xyz="-0.0201525 0 -0.0201525" />
    </visual>
    <!-- * * * Visual Definitions end * * * -->
    
    
    <!-- * * * Collision Definitions * * * -->
    <collision name='coll_ins'>
      <geometry>
        <cylinder length="0.04" radius="0.0275" />
      </geometry>
      <origin rpy="1.57075 0 0" xyz="0 0 0" />
    </collision>
    
     <collision name='coll_krom_1'>
      <geometry>
        <cylinder length="0.005" radius="0.0335" />
      </geometry>
      <origin rpy="1.57075 0 0" xyz="0 0.0175 0" />
    </collision>
  
    <collision name='coll_krom_2'>
      <geometry>
        <cylinder length="0.005" radius="0.0335" />
      </geometry>
      <origin rpy="1.57075 0 0" xyz="0 -0.0175 0" />
    </collision>
    
    <collision name='coll_tr_1'>
      <geometry>
        <box size="0.01 0.03 0.0035"/>
      </geometry>
      <origin rpy="0 0 0" xyz="0 0 0.0285" />
    </collision>
  
    <collision name='coll_tr_2'>
      <geometry>
        <box size="0.01 0.03 0.0035"/>
      </geometry>
      <origin rpy="0 0 0" xyz="0 0 -0.0285" />
    </collision>
  
  	<collision name='coll_tr_3'>
      <geometry>
        <box size="0.01 0.03 0.0035"/>
      </geometry>
      <origin rpy="0 1.57075 0" xyz="0.0285 0 0" />
    </collision>
  
    <collision name='coll_tr_4'>
      <geometry>
        <box size="0.01 0.03 0.0035"/>
      </geometry>
      <origin rpy="0 1.57075 0" xyz="-0.0285 0 0" />
    </collision>
  
    <collision name='coll_tr_5'>
      <geometry>
        <box size="0.01 0.03 0.0035"/>
      </geometry>
      <origin rpy="0 -0.785398 0" xyz="-0.0201525 0 0.0201525" />
    </collision>
  
    <collision name='coll_tr_6'>
      <geometry>
        <box size="0.01 0.03 0.0035"/>
      </geometry>
      <origin rpy="0 -0.785398 0" xyz="0.0201525 0 -0.0201525" />
    </collision>
  
  	<collision name='coll_tr_7'>
      <geometry>
        <box size="0.01 0.03 0.0035"/>
      </geometry>
      <origin rpy="0 0.785398 0" xyz="0.0201525 0 0.0201525" />
    </collision>
  
    <collision name='coll_tr_8'>
      <geometry>
        <box size="0.01 0.03 0.0035"/>
      </geometry>
      <origin rpy="0 0.785398 0" xyz="-0.0201525 0 -0.0201525" />
    </collision>
    <!-- * * * Collision Definitions end * * * -->

  </link>


  <link name="left_wheel_forw">
    
    <!-- * * * Inertial Definitions * * * -->
    <inertial>
      <mass value="0.012"/>
      <origin xyz="0 0 0" rpy=" 0 0 0"/>
      <inertia
          ixx="0.01" ixy="0" ixz="0"
          iyy="0.01" iyz="0"
          izz="0.01"
      />
    </inertial>
    <!-- * * * Inertial Definitions end * * * -->
    
    <!-- * * * Visual Definitions * * * -->
    <visual name='ins'>
      <geometry>
        <cylinder length="0.04" radius="0.0275" />
      </geometry>
      <origin rpy="1.57075 0 0" xyz="0 0 0" />
    </visual>
    
   <visual name='krom_1'>
      <geometry>
        <cylinder length="0.005" radius="0.0335" />
      </geometry>
      <origin rpy="1.57075 0 0" xyz="0 0.0175 0" />
    </visual>
  
    <visual name='krom_2'>
      <geometry>
        <cylinder length="0.005" radius="0.0335" />
      </geometry>
      <origin rpy="1.57075 0 0" xyz="0 -0.0175 0" />
    </visual>
  
    <visual name='tr_1'>
      <geometry>
        <box size="0.01 0.03 0.0035"/>
      </geometry>
      <origin rpy="0 0 0" xyz="0 0 0.0285" />
    </visual>
  
    <visual name='tr_2'>
      <geometry>
        <box size="0.01 0.03 0.0035"/>
      </geometry>
      <origin rpy="0 0 0" xyz="0 0 -0.0285" />
    </visual>
  
  	<visual name='tr_3'>
      <geometry>
        <box size="0.01 0.03 0.0035"/>
      </geometry>
      <origin rpy="0 1.57075 0" xyz="0.0285 0 0" />
    </visual>
  
    <visual name='tr_4'>
      <geometry>
        <box size="0.01 0.03 0.0035"/>
      </geometry>
      <origin rpy="0 1.57075 0" xyz="-0.0285 0 0" />
    </visual>
  
    <visual name='tr_5'>
      <geometry>
        <box size="0.01 0.03 0.0035"/>
      </geometry>
      <origin rpy="0 -0.785398 0" xyz="-0.0201525 0 0.0201525" />
    </visual>
  
    <visual name='tr_6'>
      <geometry>
        <box size="0.01 0.03 0.0035"/>
      </geometry>
      <origin rpy="0 -0.785398 0" xyz="0.0201525 0 -0.0201525" />
    </visual>
  
  	<visual name='tr_7'>
      <geometry>
        <box size="0.01 0.03 0.0035"/>
      </geometry>
      <origin rpy="0 0.785398 0" xyz="0.0201525 0 0.0201525" />
    </visual>
  
    <visual name='tr_8'>
      <geometry>
        <box size="0.01 0.03 0.0035"/>
      </geometry>
      <origin rpy="0 0.785398 0" xyz="-0.0201525 0 -0.0201525" />
    </visual>
    <!-- * * * Visual Definitions end * * * -->
    
    
    <!-- * * * Collision Definitions * * * -->
    <collision name='coll_ins'>
      <geometry>
        <cylinder length="0.04" radius="0.0275" />
      </geometry>
      <origin rpy="1.57075 0 0" xyz="0 0 0" />
    </collision>
    
     <collision name='coll_krom_1'>
      <geometry>
        <cylinder length="0.005" radius="0.0335" />
      </geometry>
      <origin rpy="1.57075 0 0" xyz="0 0.0175 0" />
    </collision>
  
    <collision name='coll_krom_2'>
      <geometry>
        <cylinder length="0.005" radius="0.0335" />
      </geometry>
      <origin rpy="1.57075 0 0" xyz="0 -0.0175 0" />
    </collision>
    
    <collision name='coll_tr_1'>
      <geometry>
        <box size="0.01 0.03 0.0035"/>
      </geometry>
      <origin rpy="0 0 0" xyz="0 0 0.0285" />
    </collision>
  
    <collision name='coll_tr_2'>
      <geometry>
        <box size="0.01 0.03 0.0035"/>
      </geometry>
      <origin rpy="0 0 0" xyz="0 0 -0.0285" />
    </collision>
  
  	<collision name='coll_tr_3'>
      <geometry>
        <box size="0.01 0.03 0.0035"/>
      </geometry>
      <origin rpy="0 1.57075 0" xyz="0.0285 0 0" />
    </collision>
  
    <collision name='coll_tr_4'>
      <geometry>
        <box size="0.01 0.03 0.0035"/>
      </geometry>
      <origin rpy="0 1.57075 0" xyz="-0.0285 0 0" />
    </collision>
  
    <collision name='coll_tr_5'>
      <geometry>
        <box size="0.01 0.03 0.0035"/>
      </geometry>
      <origin rpy="0 -0.785398 0" xyz="-0.0201525 0 0.0201525" />
    </collision>
  
    <collision name='coll_tr_6'>
      <geometry>
        <box size="0.01 0.03 0.0035"/>
      </geometry>
      <origin rpy="0 -0.785398 0" xyz="0.0201525 0 -0.0201525" />
    </collision>
  
  	<collision name='coll_tr_7'>
      <geometry>
        <box size="0.01 0.03 0.0035"/>
      </geometry>
      <origin rpy="0 0.785398 0" xyz="0.0201525 0 0.0201525" />
    </collision>
  
    <collision name='coll_tr_8'>
      <geometry>
        <box size="0.01 0.03 0.0035"/>
      </geometry>
      <origin rpy="0 0.785398 0" xyz="-0.0201525 0 -0.0201525" />
    </collision>
    <!-- * * * Collision Definitions end * * * -->

  </link>





  <joint type="continuous" name="left_wheel_forw">
    <origin xyz="0.06975 0.08 -0.0385" rpy="0 0.392699 0"/>
    <child link="left_wheel_forw"/>
    <parent link="chassis"/>
    <axis xyz="0 1 0" rpy="0 0 0"/>
    <limit effort="100" velocity="100"/>
    <joint_properties damping="0.0" friction="0.0"/>
  </joint>

  <joint type="continuous" name="right_wheel_forw">
    <origin xyz="0.06975 -0.08 -0.0385" rpy="0 0.392699 0"/>
    <child link="right_wheel_forw"/>
    <parent link="chassis"/>
    <axis xyz="0 1 0" rpy="0 0 0"/>
    <limit effort="100" velocity="100"/>
    <joint_properties damping="0.0" friction="0.0"/>
  </joint>
  
  
  
  
  
  
  
  
  
  
  
  
  
  
  
  
  
  
  
  <link name="rec_1">
    
    <!--self_collide>true</self_collide-->
    
    <!-- * * * Inertial Definitions * * * -->
    <inertial>
      <mass value="0.001"/>
      <origin xyz="0.04 0 0" rpy=" 0 0 0"/>
      <inertia
          ixx="0.0" ixy="0" ixz="0"
          iyy="0.0" iyz="0"
          izz="0.0"
      />
    </inertial>
    <!-- * * * Inertial Definitions end * * * -->
    
    <!-- * * * Visual Definitions * * * -->
    <visual name='vis_rec'>
      <geometry>
        <cylinder length="0.08" radius="0.015" />
      </geometry>
      <origin rpy="0 1.57075 0" xyz="0.04 0 0" />
    </visual>
    <!-- * * * Visual Definitions end * * * -->
    
    
    <!-- * * * Collision Definitions * * * -->
    <collision name='coll_rec'>
      <geometry>
        <cylinder length="0.08" radius="0.015" />
      </geometry>
      <origin rpy="0 1.57075 0" xyz="0.04 0 0" />
    </collision>
    <!-- * * * Collision Definitions end * * * -->

  </link>
  
  <joint type="continuous" name="rec1_to0">
    <origin xyz="0.1 0 0" rpy="0 0 0"/>
    <child link="rec_1"/>
    <parent link="chassis"/>
    <axis xyz="0 0 1" rpy="0 0 0"/>
    <limit effort="100" velocity="100"/>
    <joint_properties damping="0.0" friction="0.0"/>
  </joint>
  
  
  
  
  
  
  
  
  
  
  
  
  
  
  
  
  
  
  
  
  
  
  
  
  
  
  
  
  
  
  <!-- * * * Tracks start * * * -->
  <!-- * * * Tracks start * * * -->
  <!-- * * * Tracks start * * * -->
  <!-- * * * Tracks start * * * -->
  <!-- * * * Tracks start * * * -->
  
  <!-- * * * LEFT * * * -->
  <!--link name="track_1">
  	
  	<inertial>
      <mass value="0.0101"/>
      <origin xyz="0.011390873 0 0" rpy=" 0 0 0"/>
      <inertia
          ixx="0.01" ixy="0" ixz="0"
          iyy="0.01" iyz="0"
          izz="0.01"
      />
    </inertial>
  	
    <collision name='coll'>
      <geometry>
        <box size="0.01 0.029 0.005"/>
      </geometry>
      <origin rpy="0 0 0" xyz="0.011390873 0 0" />
    </collision>
    
    <visual name='vis'>
      <geometry>
        <box size="0.01 0.029 0.005"/>
      </geometry>
      <origin rpy="0 0 0" xyz="0.011390873 0 0" />
    </visual>
  </link>
  
  <joint type="floating" name="track_to_left_chassis">
    <origin xyz="0.058359127 0.08 -0.011" rpy="0 0 0"/>
    <child link="track_1"/>
    <parent link="chassis"/>
  </joint>
  
  
  
  
  
  <link name="track_2">
  	
  	<inertial>
      <mass value="0.0101"/>
      <origin xyz="0.011390873 0 0" rpy=" 0 0 0"/>
      <inertia
          ixx="0.01" ixy="0" ixz="0"
          iyy="0.01" iyz="0"
          izz="0.01"
      />
    </inertial>
  	
    <collision name='coll'>
      <geometry>
        <box size="0.01 0.029 0.005"/>
      </geometry>
      <origin rpy="0 0 0" xyz="0.011390873 0 0" />
    </collision>
    
    <visual name='vis'>
      <geometry>
        <box size="0.01 0.029 0.005"/>
      </geometry>
      <origin rpy="0 0 0" xyz="0.011390873 0 0" />
    </visual>
  </link>
  
  <joint type="continuous" name="track2_to_track1">
    <axis xyz="0 1 0" rpy="0 0 0"/>
    <origin xyz="0 0 0" rpy="0 0.785398 0"/>
    <child link="track_2"/>
    <parent link="track_1"/>
  </joint>
  
  
  
  
  
  <link name="track_3">
  	
  	<inertial>
      <mass value="0.0101"/>
      <origin xyz="0.011390873 0 0" rpy=" 0 0 0"/>
      <inertia
          ixx="0.01" ixy="0" ixz="0"
          iyy="0.01" iyz="0"
          izz="0.01"
      />
    </inertial>
  	
    <collision name='coll'>
      <geometry>
        <box size="0.01 0.029 0.005"/>
      </geometry>
      <origin rpy="0 0 0" xyz="0.011390873 0 0" />
    </collision>
    
    <visual name='vis'>
      <geometry>
        <box size="0.01 0.029 0.005"/>
      </geometry>
      <origin rpy="0 0 0" xyz="0.011390873 0 0" />
    </visual>
  </link>
  
  <joint type="continuous" name="track3_to_track2">
    <axis xyz="0 1 0" rpy="0 0 0"/>
    <origin xyz="0.022781746 0 0" rpy="0 0.785398 0"/>
    <child link="track_3"/>
    <parent link="track_2"/>
  </joint>
  
  
  
  
  <link name="track_4">
  	
  	<inertial>
      <mass value="0.0101"/>
      <origin xyz="0.011390873 0 0" rpy=" 0 0 0"/>
      <inertia
          ixx="0.01" ixy="0" ixz="0"
          iyy="0.01" iyz="0"
          izz="0.01"
      />
    </inertial>
  	
    <collision name='coll'>
      <geometry>
        <box size="0.01 0.029 0.005"/>
      </geometry>
      <origin rpy="0 0 0" xyz="0.011390873 0 0" />
    </collision>
    
    <visual name='vis'>
      <geometry>
        <box size="0.01 0.029 0.005"/>
      </geometry>
      <origin rpy="0 0 0" xyz="0.011390873 0 0" />
    </visual>
  </link>
  
  <joint type="continuous" name="track4_to_track3">
    <axis xyz="0 1 0" rpy="0 0 0"/>
    <origin xyz="0.022781746 0 0" rpy="0 0.785398 0"/>
    <child link="track_4"/>
    <parent link="track_3"/>
  </joint>
  
  
  
  
  
  
  <link name="track_5">
  	
  	<inertial>
      <mass value="0.0101"/>
      <origin xyz="0.011390873 0 0" rpy=" 0 0 0"/>
      <inertia
          ixx="0.01" ixy="0" ixz="0"
          iyy="0.01" iyz="0"
          izz="0.01"
      />
    </inertial>
  	
    <collision name='coll'>
      <geometry>
        <box size="0.01 0.029 0.005"/>
      </geometry>
      <origin rpy="0 0 0" xyz="0.011390873 0 0" />
    </collision>
    
    <visual name='vis'>
      <geometry>
        <box size="0.01 0.029 0.005"/>
      </geometry>
      <origin rpy="0 0 0" xyz="0.011390873 0 0" />
    </visual>
  </link>
  
  <joint type="continuous" name="track5_to_track4">
    <axis xyz="0 1 0" rpy="0 0 0"/>
    <origin xyz="0.022781746 0 0" rpy="0 0.785398 0"/>
    <child link="track_5"/>
    <parent link="track_4"/>
  </joint>
  
  
  
  
  <link name="track_6">
  	
  	<inertial>
      <mass value="0.0101"/>
      <origin xyz="0.011390873 0 0" rpy=" 0 0 0"/>
      <inertia
          ixx="0.01" ixy="0" ixz="0"
          iyy="0.01" iyz="0"
          izz="0.01"
      />
    </inertial>
  	
    <collision name='coll'>
      <geometry>
        <box size="0.01 0.029 0.005"/>
      </geometry>
      <origin rpy="0 0 0" xyz="0.011390873 0 0" />
    </collision>
    
    <visual name='vis'>
      <geometry>
        <box size="0.01 0.029 0.005"/>
      </geometry>
      <origin rpy="0 0 0" xyz="0.011390873 0 0" />
    </visual>
  </link>
  
  <joint type="continuous" name="track6_to_track5">
    <axis xyz="0 1 0" rpy="0 0 0"/>
    <origin xyz="0.022781746 0 0" rpy="0 0.785398 0"/>
    <child link="track_6"/>
    <parent link="track_5"/>
  </joint>
  
  
  
  
  
  <link name="track_7">
  	
  	<inertial>
      <mass value="0.0101"/>
      <origin xyz="0.011390873 0 0" rpy=" 0 0 0"/>
      <inertia
          ixx="0.01" ixy="0" ixz="0"
          iyy="0.01" iyz="0"
          izz="0.01"
      />
    </inertial>
  	
    <collision name='coll'>
      <geometry>
        <box size="0.01 0.029 0.005"/>
      </geometry>
      <origin rpy="0 0 0" xyz="0.011390873 0 0" />
    </collision>
    
    <visual name='vis'>
      <geometry>
        <box size="0.01 0.029 0.005"/>
      </geometry>
      <origin rpy="0 0 0" xyz="0.011390873 0 0" />
    </visual>
  </link>
  
  <joint type="continuous" name="track7_to_track6">
    <axis xyz="0 1 0" rpy="0 0 0"/>
    <origin xyz="0.022781746 0 0" rpy="0 0.785398 0"/>
    <child link="track_7"/>
    <parent link="track_6"/>
  </joint>
  
  
  
  
  
  <link name="track_8">
  	
  	<inertial>
      <mass value="0.0101"/>
      <origin xyz="0.011390873 0 0" rpy=" 0 0 0"/>
      <inertia
          ixx="0.01" ixy="0" ixz="0"
          iyy="0.01" iyz="0"
          izz="0.01"
      />
    </inertial>
  	
    <collision name='coll'>
      <geometry>
        <box size="0.01 0.029 0.005"/>
      </geometry>
      <origin rpy="0 0 0" xyz="0.011390873 0 0" />
    </collision>
    
    <visual name='vis'>
      <geometry>
        <box size="0.01 0.029 0.005"/>
      </geometry>
      <origin rpy="0 0 0" xyz="0.011390873 0 0" />
    </visual>
  </link>
  
  <joint type="continuous" name="track8_to_track7">
    <axis xyz="0 1 0" rpy="0 0 0"/>
    <origin xyz="0.022781746 0 0" rpy="0 0.785398 0"/>
    <child link="track_8"/>
    <parent link="track_7"/>
  </joint-->
  
  
  
  
  <!--joint type="continuous" name="track1_to_track8">
    <axis xyz="0 1 0" rpy="0 0 0"/>
    <origin xyz="0.022781746 0 0" rpy="0 0.785398 0"/>
    <child link="track_1"/>
    <parent link="track_8"/>
  </joint-->
  
  <!-- * * * LEFT_END * * * -->
  
  
  
  <!-- * * * RIGHT * * * -->
  
  <!-- * * * RIGHT_END * * * -->
  

  <!-- * * * Tracks end * * * -->
  <!-- * * * Tracks end * * * -->
  <!-- * * * Tracks end * * * -->
  <!-- * * * Tracks end * * * -->
  <!-- * * * Tracks end * * * -->


  
  <!--link name="test_box"-->
  
  	<!--self_collide>true</self_collide-->
  	
  	<!--inertial>
      <mass value="1"/>
      <origin xyz="0 0 0" rpy=" 0 0 0"/>
      <inertia
          ixx="1.0" ixy="0" ixz="0"
          iyy="1.0" iyz="0"
          izz="1.0"
      />
    </inertial>
  	
    <collision name='coll'>
      
      <geometry>
        <box size="0.2 0.2 0.2"/>
      </geometry>
      <origin rpy="0 0 0" xyz="0 0 0" /-->
      
      <!--surface>
        <friction>
         <ode>
           <mu>0.01</mu>
           <mu2>0.01</mu2>
           <fdir1>0 0 1</fdir1>
           <slip1>1.0</slip1>
           <slip2>1.0</slip2>
         </ode>
        </friction>
       <contact>
         <ode>
           <self_collide>true</self_collide>
           <min_depth>0.000000</min_depth>
           <kp>1000000.000000</kp>
           <kd>1.000000</kd>
           <max_vel>100.000000</max_vel>
         </ode>
       </contact>
     </surface-->
    <!--/collision>
    
    <visual name='vis'>
      <geometry>
        <box size="0.2 0.2 0.2"/>
      </geometry>
      <origin rpy="0 0 0" xyz="0 0 0" />
    </visual>
  </link>
  
  <joint type="floating" name="testy">
    <origin xyz="0.3 0 0" rpy="0 0 0"/>
    <child link="test_box"/>
    <parent link="chassis"/>
  </joint-->

</robot>


     


